2019-08-30 15:30:34 [INFO] - [client] recieved a connector from /192.168.2.55:7881
2019-08-30 15:31:00 [WARN] - An exceptionCaught() event was fired, and it reached at the tail of the pipeline. It usually means the last handler in the pipeline did not handle the exception.
java.io.IOException: 远程主机强迫关闭了一个现有的连接。
	at sun.nio.ch.SocketDispatcher.read0(Native Method)
	at sun.nio.ch.SocketDispatcher.read(Unknown Source)
	at sun.nio.ch.IOUtil.readIntoNativeBuffer(Unknown Source)
	at sun.nio.ch.IOUtil.read(Unknown Source)
	at sun.nio.ch.SocketChannelImpl.read(Unknown Source)
	at io.netty.buffer.PooledUnsafeDirectByteBuf.setBytes(PooledUnsafeDirectByteBuf.java:288)
	at io.netty.buffer.AbstractByteBuf.writeBytes(AbstractByteBuf.java:1125)
	at io.netty.channel.socket.nio.NioSocketChannel.doReadBytes(NioSocketChannel.java:347)
	at io.netty.channel.nio.AbstractNioByteChannel$NioByteUnsafe.read(AbstractNioByteChannel.java:148)
	at io.netty.channel.nio.NioEventLoop.processSelectedKey(NioEventLoop.java:682)
	at io.netty.channel.nio.NioEventLoop.processSelectedKeysOptimized(NioEventLoop.java:617)
	at io.netty.channel.nio.NioEventLoop.processSelectedKeys(NioEventLoop.java:534)
	at io.netty.channel.nio.NioEventLoop.run(NioEventLoop.java:496)
	at io.netty.util.concurrent.SingleThreadEventExecutor$5.run(SingleThreadEventExecutor.java:906)
	at io.netty.util.internal.ThreadExecutorMap$2.run(ThreadExecutorMap.java:74)
	at io.netty.util.concurrent.FastThreadLocalRunnable.run(FastThreadLocalRunnable.java:30)
	at java.lang.Thread.run(Unknown Source)
